<?xml version="1.0"?>
<robot name="wheel_leg_robot">

  <link name="world"/>

  <link name="base_link">
    <visual>
      <origin xyz="0 0 0" rpy="0 1.5708 0"/>
      <geometry>
        <mesh filename="package://wheel_leg_description/meshes/visual/shell_and_big_motor.stl"
              scale="0.001 0.001 0.001"/>
      </geometry>
      <material name="base_gray">
        <color rgba="0.65 0.65 0.65 1"/>
      </material>
    </visual>
  </link>

  <joint name="world_to_base" type="fixed">
    <parent link="world"/>
    <child link="base_link"/>
    <origin xyz="0 0 0" rpy="0 0 0"/>
  </joint>


  <!-- big_arm_1 -->
  <link name="big_arm_1_link">
    <visual>
      <origin xyz="-0.231306 -0.053564 -0.030643" rpy="0 1.5708 0"/>
      <geometry>
        <mesh filename="package://wheel_leg_description/meshes/visual/big_arm_1.stl"
              scale="0.001 0.001 0.001"/>
      </geometry>
    </visual>
  </link>

  <joint name="big_arm_1_joint" type="revolute">
    <parent link="base_link"/>
    <child link="big_arm_1_link"/>
    <origin xyz="0.231306 0.053564 0.030643" rpy="0 0 0"/>
    <axis xyz="0 1 0"/>
    <limit lower="-1.57" upper="1.57" effort="20" velocity="10"/>
  </joint>


  <!-- big_arm_2 -->
  <link name="big_arm_2_link">
    <visual>
      <origin xyz="-0.161440 -0.053564 -0.026313" rpy="0 1.5708 0"/>
      <geometry>
        <mesh filename="package://wheel_leg_description/meshes/visual/big_arm_2.stl"
              scale="0.001 0.001 0.001"/>
      </geometry>
    </visual>
  </link>

  <joint name="big_arm_2_joint" type="revolute">
    <parent link="base_link"/>
    <child link="big_arm_2_link"/>
    <origin xyz="0.161440 0.053564 0.026313" rpy="0 0 0"/>
    <axis xyz="0 1 0"/>
    <limit lower="-1.57" upper="1.57" effort="20" velocity="10"/>
  </joint>


  <!-- big_arm_3 -->
  <link name="big_arm_3_link">
    <visual>
      <origin xyz="-0.231306 0.048436 -0.030643" rpy="0 1.5708 0"/>
      <geometry>
        <mesh filename="package://wheel_leg_description/meshes/visual/big_arm_3.stl"
              scale="0.001 0.001 0.001"/>
      </geometry>
    </visual>
  </link>

  <joint name="big_arm_3_joint" type="revolute">
    <parent link="base_link"/>
    <child link="big_arm_3_link"/>
    <origin xyz="0.231306 -0.048436 0.030643" rpy="0 0 0"/>
    <axis xyz="0 1 0"/>
    <limit lower="-1.57" upper="1.57" effort="20" velocity="10"/>
  </joint>


  <!-- big_arm_4 -->
  <link name="big_arm_4_link">
    <visual>
      <origin xyz="-0.161440 0.048436 -0.026313" rpy="0 1.5708 0"/>
      <geometry>
        <mesh filename="package://wheel_leg_description/meshes/visual/big_arm_4.stl"
              scale="0.001 0.001 0.001"/>
      </geometry>
    </visual>
  </link>

  <joint name="big_arm_4_joint" type="revolute">
    <parent link="base_link"/>
    <child link="big_arm_4_link"/>
    <origin xyz="0.161440 -0.048436 0.026313" rpy="0 0 0"/>
    <axis xyz="0 1 0"/>
    <limit lower="-1.57" upper="1.57" effort="20" velocity="10"/>
  </joint>


  <!-- small leg and wheel parts are fixed temporarily -->
  <link name="small_leggy_1_link">
    <visual>
      <origin xyz="0 0 0" rpy="0 1.5708 0"/>
      <geometry>
        <mesh filename="package://wheel_leg_description/meshes/visual/small_leggy_1.stl"
              scale="0.001 0.001 0.001"/>
      </geometry>
    </visual>
  </link>

  <joint name="base_to_small_leggy_1" type="fixed">
    <parent link="base_link"/>
    <child link="small_leggy_1_link"/>
    <origin xyz="0 0 0" rpy="0 0 0"/>
  </joint>


  <link name="small_leggy_2_link">
    <visual>
      <origin xyz="0 0 0" rpy="0 1.5708 0"/>
      <geometry>
        <mesh filename="package://wheel_leg_description/meshes/visual/small_leggy_2.stl"
              scale="0.001 0.001 0.001"/>
      </geometry>
    </visual>
  </link>

  <joint name="base_to_small_leggy_2" type="fixed">
    <parent link="base_link"/>
    <child link="small_leggy_2_link"/>
    <origin xyz="0 0 0" rpy="0 0 0"/>
  </joint>


  <link name="small_leg_wheel_1_link">
    <visual>
      <origin xyz="0 0 0" rpy="0 1.5708 0"/>
      <geometry>
        <mesh filename="package://wheel_leg_description/meshes/visual/small_leg_wheel_1.stl"
              scale="0.001 0.001 0.001"/>
      </geometry>
    </visual>
  </link>

  <joint name="base_to_small_leg_wheel_1" type="fixed">
    <parent link="base_link"/>
    <child link="small_leg_wheel_1_link"/>
    <origin xyz="0 0 0" rpy="0 0 0"/>
  </joint>


  <link name="small_leg_wheel_2_link">
    <visual>
      <origin xyz="0 0 0" rpy="0 1.5708 0"/>
      <geometry>
        <mesh filename="package://wheel_leg_description/meshes/visual/small_leg_wheel_2.stl"
              scale="0.001 0.001 0.001"/>
      </geometry>
    </visual>
  </link>

  <joint name="base_to_small_leg_wheel_2" type="fixed">
    <parent link="base_link"/>
    <child link="small_leg_wheel_2_link"/>
    <origin xyz="0 0 0" rpy="0 0 0"/>
  </joint>


  <link name="wheel_motor_1_link">
    <visual>
      <origin xyz="0 0 0" rpy="0 1.5708 0"/>
      <geometry>
        <mesh filename="package://wheel_leg_description/meshes/visual/wheel_motor_1.stl"
              scale="0.001 0.001 0.001"/>
      </geometry>
    </visual>
  </link>

  <joint name="base_to_wheel_motor_1" type="fixed">
    <parent link="base_link"/>
    <child link="wheel_motor_1_link"/>
    <origin xyz="0 0 0" rpy="0 0 0"/>
  </joint>


  <link name="wheel_motor_2_link">
    <visual>
      <origin xyz="0 0 0" rpy="0 1.5708 0"/>
      <geometry>
        <mesh filename="package://wheel_leg_description/meshes/visual/wheel_motor_2.stl"
              scale="0.001 0.001 0.001"/>
      </geometry>
    </visual>
  </link>

  <joint name="base_to_wheel_motor_2" type="fixed">
    <parent link="base_link"/>
    <child link="wheel_motor_2_link"/>
    <origin xyz="0 0 0" rpy="0 0 0"/>
  </joint>

</robot>
